Workbook

Sheet Dashboard
A1: MACRO ECONOMIC MONITORING DASHBOARD
A2: Last Updated: | B2: 2026-02-08
A4: Indicator | B4: Current Value | C4: Previous Value | D4: Signal / Threshold | E4: Status
A5: INTEREST RATES & YIELDS
A6: Fed Funds Rate (%) | D6: FEDFUNDS | E6: =IF(B6>5,"Restrictive",IF(B6>2.5,"Neutral","Accommodative"))
A7: 10-Year Treasury Yield (%) | D7: DGS10 | E7: =IF(B7>4.5,"High",IF(B7>3,"Normal","Low"))
A8: 2-Year Treasury Yield (%) | D8: DGS2 | E8: =IF(B8>4.5,"High",IF(B8>3,"Normal","Low"))
A9: Yield Curve 10Y-2Y (bp) | B9: =((B7-B8)*100) | D9: IF(B9<0 | E9: =IF(B9<0,"INVERTED - Recession Signal",IF(B9<50,"Flat","Normal"))
A10: 10-Year TIPS Yield (%) | D10: DFII10 | E10: =IF(B10>2,"Tight",IF(B10>0,"Moderate","Loose"))
A11: 10-Year Breakeven Inflation (%) | D11: T10YIE | E11: =IF(B11>3,"High Inflation Expected",IF(B11>2,"Normal","Low Inflation Expected"))
A12: REAL INTEREST RATES (Key Driver)
A13: Real Fed Funds Rate (%) | B13: =(B6-B18) | D13: Auto-calculated | E13: =IF(B13>2,"Very Tight",IF(B13>0,"Tight",IF(B13>-1,"Neutral","Loose")))
A14: Real 10Y Rate (TIPS) (%) | B14: =B10 | D14: Auto-calculated | E14: =IF(B14>2,"Very Tight",IF(B14>0.5,"Tight",IF(B14>-0.5,"Neutral","Loose")))
A15: Real 10Y Rate (Fisher) (%) | B15: =(B7-B18) | D15: Auto-calculated | E15: =IF(B15>2,"Very Tight",IF(B15>0.5,"Tight",IF(B15>-0.5,"Neutral","Loose")))
A17: INFLATION METRICS
A18: CPI Year-over-Year (%) | D18: CPIAUCSL | E18: =IF(B18>5,"Very High",IF(B18>3,"Elevated",IF(B18>2,"Normal","Low")))
A19: Core PCE Year-over-Year (%) | D19: PCEPILFE | E19: =IF(B19>4,"Very High",IF(B19>2.5,"Above Target",IF(B19>1.5,"At Target","Below Target")))
A20: CPI Month-over-Month (%) | D20: CPIAUCSL_MOM | E20: =IF(B20>0.4,"Hot",IF(B20>0.2,"Warm","Cool"))
A21: 5Y5Y Forward Inflation (%) | D21: T5YIFR | E21: =IF(B21>3,"Unanchored High",IF(B21>2,"Anchored","Unanchored Low"))
A23: CREDIT CONDITIONS & SPREADS
A24: HY OAS Spread (bp) | D24: BAMLH0A0HYM2 | E24: =IF(B24>600,"Stress",IF(B24>400,"Elevated",IF(B24>300,"Normal","Tight")))
A25: IG OAS Spread (bp) | D25: BAMLC0A0CM | E25: =IF(B25>200,"Stress",IF(B25>130,"Elevated",IF(B25>80,"Normal","Tight")))
A26: BBB-AA Spread (bp) | B26: =(B25-B27) | D26: Auto-calculated | E26: =IF(B26>100,"Quality Flight",IF(B26>60,"Elevated","Normal"))
A27: AA OAS Spread (bp) | D27: BAMLC0A3CA | E27: =IF(B27>100,"Stress",IF(B27>60,"Elevated","Normal"))
A28: TED Spread (bp) | D28: TEDRATE | E28: =IF(B28>100,"Banking Stress",IF(B28>50,"Elevated","Normal"))
A30: LABOR MARKET
A31: Unemployment Rate (%) | D31: UNRATE | E31: =IF(B31>6,"Recession",IF(B31>5,"Weakening",IF(B31>3.5,"Normal","Tight")))
A32: Nonfarm Payrolls (k) | D32: PAYEMS | E32: =IF(B32<0,"Contraction",IF(B32<100,"Slowing",IF(B32<250,"Normal","Strong")))
A33: Initial Claims (k) | D33: ICSA | E33: =IF(B33>300,"Recession Risk",IF(B33>250,"Elevated","Normal"))
A34: JOLTS Openings (M) | D34: JTSJOL | E34: =IF(B34<7,"Weak",IF(B34<9,"Normal","Very Tight"))
A36: GROWTH & ACTIVITY
A37: GDP Growth QoQ Annualized (%) | D37: GDP | E37: =IF(B37<0,"Contraction",IF(B37<1,"Stall Speed",IF(B37<3,"Normal","Strong")))
A38: ISM Manufacturing PMI | D38: MANEMP | E38: =IF(B38<45,"Deep Contraction",IF(B38<50,"Contraction",IF(B38<55,"Expansion","Strong Expansion")))
A39: ISM Services PMI | D39: NMFCI | E39: =IF(B39<45,"Deep Contraction",IF(B39<50,"Contraction",IF(B39<55,"Expansion","Strong Expansion")))
A40: Leading Economic Index (MoM %) | D40: LEI | E40: =IF(B40<-0.5,"Recession Signal",IF(B40<0,"Warning","Expansionary"))
A42: MARKET INDICATORS
A43: S&P 500 Level | D43: SP500 | E43: =IF(B43>B44,"Above 200 DMA","Below 200 DMA")
A44: S&P 500 200-Day MA | D44: SP500_200DMA | E44: Reference level
A45: VIX | D45: VIXCLS | E45: =IF(B45>30,"Fear",IF(B45>20,"Elevated",IF(B45>12,"Normal","Complacent")))
A47: REGIME DETECTION
...

Sheet Historical Tracking
A1: Date | B1: Fed Funds | C1: 10Y Yield | D1: 10Y TIPS | E1: Breakeven | F1: CPI YoY | G1: Core PCE | H1: HY Spread | I1: IG Spread | J1: Unemployment | K1: NFP (k) | L1: GDP QoQ | M1: ISM Mfg | N1: ISM Svc | O1: VIX | P1: Yield Curve | Q1: Real Rate | R1: Regime
A2: =Dashboard!B2 | B2: =Dashboard!B6 | C2: =Dashboard!B7 | D2: =Dashboard!B10 | E2: =Dashboard!B11 | F2: =Dashboard!B18 | G2: =Dashboard!B19 | H2: =Dashboard!B24 | I2: =Dashboard!B25 | J2: =Dashboard!B31 | K2: =Dashboard!B32 | L2: =Dashboard!B37 | M2: =Dashboard!B38 | N2: =Dashboard!B39 | O2: =Dashboard!B45 | P2: =Dashboard!B9 | Q2: =Dashboard!B14 | R2: =Dashboard!B52

Sheet Zombie Screener
A1: ZOMBIE COMPANY SCREENER
A2: Identify companies that cannot cover interest payments from operating income
A4: Company | B4: Ticker | C4: Sector | D4: Interest Coverage (EBIT/Interest) | E4: Debt/EBITDA | F4: Free Cash Flow ($M) | G4: Debt Maturity Wall (Year) | H4: Credit Rating | I4: CDS Spread (bp) | J4: Zombie Score (0-10)
J5: =IF(D5="","",(IF(D5<1,3,IF(D5<2,2,0))+IF(E5>6,2,IF(E5>4,1,0))+IF(F5<0,2,0)+IF(AND(G5<>"",(G5-YEAR(TODAY()))<=2),2,0)+IF(OR(H5="CCC",H5="CC",H5="C",H5="D"),1,0)))
J6: =IF(D6="","",(IF(D6<1,3,IF(D6<2,2,0))+IF(E6>6,2,IF(E6>4,1,0))+IF(F6<0,2,0)+IF(AND(G6<>"",(G6-YEAR(TODAY()))<=2),2,0)+IF(OR(H6="CCC",H6="CC",H6="C",H6="D"),1,0)))
J7: =IF(D7="","",(IF(D7<1,3,IF(D7<2,2,0))+IF(E7>6,2,IF(E7>4,1,0))+IF(F7<0,2,0)+IF(AND(G7<>"",(G7-YEAR(TODAY()))<=2),2,0)+IF(OR(H7="CCC",H7="CC",H7="C",H7="D"),1,0)))
J8: =IF(D8="","",(IF(D8<1,3,IF(D8<2,2,0))+IF(E8>6,2,IF(E8>4,1,0))+IF(F8<0,2,0)+IF(AND(G8<>"",(G8-YEAR(TODAY()))<=2),2,0)+IF(OR(H8="CCC",H8="CC",H8="C",H8="D"),1,0)))
J9: =IF(D9="","",(IF(D9<1,3,IF(D9<2,2,0))+IF(E9>6,2,IF(E9>4,1,0))+IF(F9<0,2,0)+IF(AND(G9<>"",(G9-YEAR(TODAY()))<=2),2,0)+IF(OR(H9="CCC",H9="CC",H9="C",H9="D"),1,0)))
J10: =IF(D10="","",(IF(D10<1,3,IF(D10<2,2,0))+IF(E10>6,2,IF(E10>4,1,0))+IF(F10<0,2,0)+IF(AND(G10<>"",(G10-YEAR(TODAY()))<=2),2,0)+IF(OR(H10="CCC",H10="CC",H10="C",H10="D"),1,0)))
J11: =IF(D11="","",(IF(D11<1,3,IF(D11<2,2,0))+IF(E11>6,2,IF(E11>4,1,0))+IF(F11<0,2,0)+IF(AND(G11<>"",(G11-YEAR(TODAY()))<=2),2,0)+IF(OR(H11="CCC",H11="CC",H11="C",H11="D"),1,0)))
J12: =IF(D12="","",(IF(D12<1,3,IF(D12<2,2,0))+IF(E12>6,2,IF(E12>4,1,0))+IF(F12<0,2,0)+IF(AND(G12<>"",(G12-YEAR(TODAY()))<=2),2,0)+IF(OR(H12="CCC",H12="CC",H12="C",H12="D"),1,0)))
J13: =IF(D13="","",(IF(D13<1,3,IF(D13<2,2,0))+IF(E13>6,2,IF(E13>4,1,0))+IF(F13<0,2,0)+IF(AND(G13<>"",(G13-YEAR(TODAY()))<=2),2,0)+IF(OR(H13="CCC",H13="CC",H13="C",H13="D"),1,0)))
J14: =IF(D14="","",(IF(D14<1,3,IF(D14<2,2,0))+IF(E14>6,2,IF(E14>4,1,0))+IF(F14<0,2,0)+IF(AND(G14<>"",(G14-YEAR(TODAY()))<=2),2,0)+IF(OR(H14="CCC",H14="CC",H14="C",H14="D"),1,0)))
J15: =IF(D15="","",(IF(D15<1,3,IF(D15<2,2,0))+IF(E15>6,2,IF(E15>4,1,0))+IF(F15<0,2,0)+IF(AND(G15<>"",(G15-YEAR(TODAY()))<=2),2,0)+IF(OR(H15="CCC",H15="CC",H15="C",H15="D"),1,0)))
J16: =IF(D16="","",(IF(D16<1,3,IF(D16<2,2,0))+IF(E16>6,2,IF(E16>4,1,0))+IF(F16<0,2,0)+IF(AND(G16<>"",(G16-YEAR(TODAY()))<=2),2,0)+IF(OR(H16="CCC",H16="CC",H16="C",H16="D"),1,0)))
... J24: =IF(D24="","",(IF(D24<1,3,IF(D24<2,2,0))+IF(E24>6,2,IF(E24>4,1,0))+IF(F24<0,2,0)+IF(AND(G24<>"",(G24-YEAR(TODAY()))<=2),2,0)+IF(OR(H24="CCC",H24="CC",H24="C",H24="D"),1,0)))
A26: SCORING GUIDE
A27: 7-10: HIGH RISK ZOMBIE - Strong short candidate
A28: 4-6: MODERATE RISK - Watch closely, potential candidate
A29: 0-3: LOW RISK - Not a zombie, avoid shorting
A31: Key Zombie Characteristics:
A32: - Interest coverage < 1x for 3+ years
A33: - Negative free cash flow
A34: - Debt maturity wall within 2 years
A35: - Rating CCC or below
A36: - Rising CDS spreads

Sheet Portfolio Allocations
A1: PORTFOLIO ALLOCATION BY REGIME
A3: Asset Class | B3: GOLDILOCKS | C3: INFLATION RISING | D3: STAGFLATION | E3: SLOWDOWN | F3: DEFLATIONARY BUST | G3: CURRENT RECOMMENDED | H3: YOUR ALLOCATION
A4: US Equities | B4: 0.35 | C4: 0.25 | D4: 0.1 | E4: 0.2 | F4: 0.15 | G4: =IF(Dashboard!B52="GOLDILOCKS",B4,IF(Dashboard!B52="INFLATION RISING",C4,IF(OR(Dashboard!B52="STAGFLATION",Dashboard!B52="STAGFLATION WARNING"),D4,IF(Dashboard!B52="SLOWDOWN",E4,IF(Dashboard!B52="DEFLATIONARY BUST",F4,B4)))))
A5: Int'l Equities | B5: 0.15 | C5: 0.1 | D5: 0.05 | E5: 0.1 | F5: 0.05 | G5: =IF(Dashboard!B52="GOLDILOCKS",B5,IF(Dashboard!B52="INFLATION RISING",C5,IF(OR(Dashboard!B52="STAGFLATION",Dashboard!B52="STAGFLATION WARNING"),D5,IF(Dashboard!B52="SLOWDOWN",E5,IF(Dashboard!B52="DEFLATIONARY BUST",F5,B5)))))
A6: Long-Term Bonds | B6: 0.15 | C6: 0.05 | D6: 0.05 | E6: 0.25 | F6: 0.35 | G6: =IF(Dashboard!B52="GOLDILOCKS",B6,IF(Dashboard!B52="INFLATION RISING",C6,IF(OR(Dashboard!B52="STAGFLATION",Dashboard!B52="STAGFLATION WARNING"),D6,IF(Dashboard!B52="SLOWDOWN",E6,IF(Dashboard!B52="DEFLATIONARY BUST",F6,B6)))))
A7: TIPS / I-Bonds | B7: 0.05 | C7: 0.15 | D7: 0.2 | E7: 0.05 | F7: 0.05 | G7: =IF(Dashboard!B52="GOLDILOCKS",B7,IF(Dashboard!B52="INFLATION RISING",C7,IF(OR(Dashboard!B52="STAGFLATION",Dashboard!B52="STAGFLATION WARNING"),D7,IF(Dashboard!B52="SLOWDOWN",E7,IF(Dashboard!B52="DEFLATIONARY BUST",F7,B7)))))
A8: Short-Term Bonds/Cash | B8: 0.05 | C8: 0.1 | D8: 0.15 | E8: 0.15 | F8: 0.2 | G8: =IF(Dashboard!B52="GOLDILOCKS",B8,IF(Dashboard!B52="INFLATION RISING",C8,IF(OR(Dashboard!B52="STAGFLATION",Dashboard!B52="STAGFLATION WARNING"),D8,IF(Dashboard!B52="SLOWDOWN",E8,IF(Dashboard!B52="DEFLATIONARY BUST",F8,B8)))))
A9: Commodities | B9: 0.05 | C9: 0.15 | D9: 0.2 | E9: 0.05 | F9: 0 | G9: =IF(Dashboard!B52="GOLDILOCKS",B9,IF(Dashboard!B52="INFLATION RISING",C9,IF(OR(Dashboard!B52="STAGFLATION",Dashboard!B52="STAGFLATION WARNING"),D9,IF(Dashboard!B52="SLOWDOWN",E9,IF(Dashboard!B52="DEFLATIONARY BUST",F9,B9)))))
A10: Gold | B10: 0.05 | C10: 0.1 | D10: 0.15 | E10: 0.1 | F10: 0.1 | G10: =IF(Dashboard!B52="GOLDILOCKS",B10,IF(Dashboard!B52="INFLATION RISING",C10,IF(OR(Dashboard!B52="STAGFLATION",Dashboard!B52="STAGFLATION WARNING"),D10,IF(Dashboard!B52="SLOWDOWN",E10,IF(Dashboard!B52="DEFLATIONARY BUST",F10,B10)))))
A11: Real Estate (REITs) | B11: 0.1 | C11: 0.05 | D11: 0 | E11: 0.05 | F11: 0.05 | G11: =IF(Dashboard!B52="GOLDILOCKS",B11,IF(Dashboard!B52="INFLATION RISING",C11,IF(OR(Dashboard!B52="STAGFLATION",Dashboard!B52="STAGFLATION WARNING"),D11,IF(Dashboard!B52="SLOWDOWN",E11,IF(Dashboard!B52="DEFLATIONARY BUST",F11,B11)))))
A12: Crypto / Alternatives | B12: 0.05 | C12: 0.05 | D12: 0 | E12: 0 | F12: 0 | G12: =IF(Dashboard!B52="GOLDILOCKS",B12,IF(Dashboard!B52="INFLATION RISING",C12,IF(OR(Dashboard!B52="STAGFLATION",Dashboard!B52="STAGFLATION WARNING"),D12,IF(Dashboard!B52="SLOWDOWN",E12,IF(Dashboard!B52="DEFLATIONARY BUST",F12,B12)))))
A13: Zombie Shorts (via puts) | B13: 0 | C13: 0 | D13: 0.1 | E13: 0.05 | F13: 0.05 | G13: =IF(Dashboard!B52="GOLDILOCKS",B13,IF(Dashboard!B52="INFLATION RISING",C13,IF(OR(Dashboard!B52="STAGFLATION",Dashboard!B52="STAGFLATION WARNING"),D13,IF(Dashboard!B52="SLOWDOWN",E13,IF(Dashboard!B52="DEFLATIONARY BUST",F13,B13)))))
A14: TOTAL | B14: =SUM(B4:B13) | C14: =SUM(C4:C13) | D14: =SUM(D4:D13) | E14: =SUM(E4:E13) | F14: =SUM(F4:F13) | G14: =SUM(G4:G13) | H14: =SUM(H4:H13)
A16: Current Detected Regime: | D16: =Dashboard!B52
A18: SUGGESTED ETFs BY ASSET CLASS
A19: US Equities | B19: SPY, VOO, VTI, QQQ
A20: Int'l Equities | B20: VXUS, EFA, VWO, IEMG
A21: Long-Term Bonds | B21: TLT, VGLT, EDV, ZROZ
A22: TIPS / I-Bonds | B22: TIP, SCHP, VTIP, STIP
A23: Short-Term Bonds/Cash | B23: SHV, BIL, SGOV, VMFXX
A24: Commodities | B24: DBC, GSG, PDBC, COMT
A25: Gold | B25: GLD, IAU, GLDM, SGOL
A26: Real Estate | B26: VNQ, SCHH, IYR, XLRE
A27: Zombie Shorts | B27: Use put options on individual names

Sheet Data Sources
A1: DATA SOURCES & FRED SERIES CODES
A3: Indicator | B3: FRED Code | C3: URL | D3: Update Frequency | E3: Typical Release
A4: Fed Funds Rate | B4: FEDFUNDS | C4: https://fred.stlouisfed.org/series/FEDFUNDS | D4: Monthly | E4: 1st business day
A5: Fed Funds (Daily) | B5: DFF | C5: https://fred.stlouisfed.org/series/DFF | D5: Daily | E5: Next business day
A6: 10-Year Treasury | B6: DGS10 | C6: https://fred.stlouisfed.org/series/DGS10 | D6: Daily | E6: Next business day
A7: 2-Year Treasury | B7: DGS2 | C7: https://fred.stlouisfed.org/series/DGS2 | D7: Daily | E7: Next business day
A8: 10-Year TIPS | B8: DFII10 | C8: https://fred.stlouisfed.org/series/DFII10 | D8: Daily | E8: Next business day
A9: 10Y Breakeven | B9: T10YIE | C9: https://fred.stlouisfed.org/series/T10YIE | D9: Daily | E9: Next business day
A10: 5Y5Y Forward | B10: T5YIFR | C10: https://fred.stlouisfed.org/series/T5YIFR | D10: Daily | E10: Next business day
A11: CPI YoY | B11: CPIAUCSL | C11: https://fred.stlouisfed.org/series/CPIAUCSL | D11: Monthly | E11: ~13th of month
A12: Core PCE | B12: PCEPILFE | C12: https://fred.stlouisfed.org/series/PCEPILFE | D12: Monthly | E12: ~30th of month
A13: HY OAS Spread | B13: BAMLH0A0HYM2 | C13: https://fred.stlouisfed.org/series/BAMLH0A0HYM2 | D13: Daily | E13: Next business day
A14: IG OAS Spread | B14: BAMLC0A0CM | C14: https://fred.stlouisfed.org/series/BAMLC0A0CM | D14: Daily | E14: Next business day
... A23: S&P 500 | B23: SP500 | C23: https://fred.stlouisfed.org/series/SP500 | D23: Daily | E23: Next business day

Sheet Instructions
A1: MACRO MONITORING WORKBOOK - INSTRUCTIONS
A3: OVERVIEW
A4: This workbook tracks key macroeconomic indicators to detect regime changes,
A5: assess credit conditions, and guide portfolio allocation decisions.
A6: Based on 'The Price of Time' by Edward Chancellor.
A8: COLOR CODING
A9: YELLOW cells = Data entry (enter your values here)
A10: GREEN cells = Auto-calculated (formulas, do not edit)
A11: BLUE headers = Section headers
A12: RED header = Regime detection area
A14: HOW TO UPDATE
A15: 1. Go to the Dashboard sheet
... A45: - The system is a guide, not a crystal ball
